Workbook
Name in_end: Assumptions!$C$6
Name SelCat: Dashboard!$B$6
Name CatCrit: IF(Dashboard!$B$6="All","*",Dashboard!$B$6)

Sheet Dashboard
B1: SHELLY
B2: Category review
B3: Demo Neighbourhood Store (Eden Terrace format) · 13 weeks to 11 Oct 2026
B5: Category
B6: All
B7: Change the blue cell to filter the whole workbook.
B9: 13-WEEK SALES | E9: VS PRIOR 13 WEEKS | H9: GROSS MARGIN % | K9: PRODUCTS IN SELECTION
B10: =SUMIFS(Raw!$E$2:$E$1301,Raw!$D$2:$D$1301,CatCrit,Raw!$A$2:$A$1301,">"&(Assumptions!$C$6-91),Raw!$A$2:$A$1301,"<="&Assumptions!$C$6) -> 248707.06 | E10: =IFERROR(SUMIFS(Raw!$E$2:$E$1301,Raw!$D$2:$D$1301,CatCrit,Raw!$A$2:$A$1301,">"&(Assumptions!$C$6-91),Raw!$A$2:$A$1301,"<="&Assumptions!$C$6)/SUMIFS(Raw!$E$2:$E$1301,Raw!$D$2:$D$1301,CatCrit,Raw!$A$2:$A$1301,">"&(Assumptions!$C$6-182),Raw!$A$2:$A$1301,"<="&(Assumptions!$C$6-91))-1,0) -> 0.014289535 | H10: =IFERROR(SUMIFS(Raw!$G$2:$G$1301,Raw!$D$2:$D$1301,CatCrit,Raw!$A$2:$A$1301,">"&(Assumptions!$C$6-91),Raw!$A$2:$A$1301,"<="&Assumptions!$C$6)/SUMIFS(Raw!$E$2:$E$1301,Raw!$D$2:$D$1301,CatCrit,Raw!$A$2:$A$1301,">"&(Assumptions!$C$6-91),Raw!$A$2:$A$1301,"<="&Assumptions!$C$6),0) -> 0.40630101 | K10: =SUM(Model!$K$25:$K$74) -> 50

Sheet Model
B1: SHELLY
B2: Model
B3: Live formulas over Raw, Lookup and Assumptions. Nothing on this sheet is typed in.
B5: Categories (13 weeks)
B7: Category | C7: Sales 13w | D7: Prior 13w | E7: Change | F7: Gross margin | G7: GM % | H7: Share
B8: Bakery | C8: =SUMIFS(Raw!$E$2:$E$1301,Raw!$D$2:$D$1301,$B8,Raw!$A$2:$A$1301,">"&(Assumptions!$C$6-91),Raw!$A$2:$A$1301,"<="&Assumptions!$C$6) -> 14653.91 | D8: =SUMIFS(Raw!$E$2:$E$1301,Raw!$D$2:$D$1301,$B8,Raw!$A$2:$A$1301,">"&(Assumptions!$C$6-182),Raw!$A$2:$A$1301,"<="&(Assumptions!$C$6-91)) -> 14345.48 | E8: =IFERROR(C8/D8-1,0) -> 0.021500152 | F8: =SUMIFS(Raw!$G$2:$G$1301,Raw!$D$2:$D$1301,$B8,Raw!$A$2:$A$1301,">"&(Assumptions!$C$6-91),Raw!$A$2:$A$1301,"<="&Assumptions!$C$6) -> 5647.11 | G8: =IFERROR(F8/C8,0) -> 0.38536541 | H8: =IFERROR(C8/SUMIFS(Raw!$E$2:$E$1301,Raw!$A$2:$A$1301,">"&(Assumptions!$C$6-91),Raw!$A$2:$A$1301,"<="&Assumptions!$C$6),0) -> 0.058920362
B9: Beer & Wine | C9: =SUMIFS(Raw!$E$2:$E$1301,Raw!$D$2:$D$1301,$B9,Raw!$A$2:$A$1301,">"&(Assumptions!$C$6-91),Raw!$A$2:$A$1301,"<="&Assumptions!$C$6) -> 27373.6 | D9: =SUMIFS(Raw!$E$2:$E$1301,Raw!$D$2:$D$1301,$B9,Raw!$A$2:$A$1301,">"&(Assumptions!$C$6-182),Raw!$A$2:$A$1301,"<="&(Assumptions!$C$6-91)) -> 26206.84 | E9: =IFERROR(C9/D9-1,0) -> 0.044521201 | F9: =SUMIFS(Raw!$G$2:$G$1301,Raw!$D$2:$D$1301,$B9,Raw!$A$2:$A$1301,">"&(Assumptions!$C$6-91),Raw!$A$2:$A$1301,"<="&Assumptions!$C$6) -> 9307 | G9: =IFERROR(F9/C9,0) -> 0.33999912 | H9: =IFERROR(C9/SUMIFS(Raw!$E$2:$E$1301,Raw!$A$2:$A$1301,">"&(Assumptions!$C$6-91),Raw!$A$2:$A$1301,"<="&Assumptions!$C$6),0) -> 0.11006362
B10: Beverages | C10: =SUMIFS(Raw!$E$2:$E$1301,Raw!$D$2:$D$1301,$B10,Raw!$A$2:$A$1301,">"&(Assumptions!$C$6-91),Raw!$A$2:$A$1301,"<="&Assumptions!$C$6) -> 32548.7 | D10: =SUMIFS(Raw!$E$2:$E$1301,Raw!$D$2:$D$1301,$B10,Raw!$A$2:$A$1301,">"&(Assumptions!$C$6-182),Raw!$A$2:$A$1301,"<="&(Assumptions!$C$6-91)) -> 32774.3 | E10: =IFERROR(C10/D10-1,0) -> -0.0068834422 | F10: =SUMIFS(Raw!$G$2:$G$1301,Raw!$D$2:$D$1301,$B10,Raw!$A$2:$A$1301,">"&(Assumptions!$C$6-91),Raw!$A$2:$A$1301,"<="&Assumptions!$C$6) -> 16676.6 | G10: =IFERROR(F10/C10,0) -> 0.5123584 | H10: =IFERROR(C10/SUMIFS(Raw!$E$2:$E$1301,Raw!$A$2:$A$1301,">"&(Assumptions!$C$6-91),Raw!$A$2:$A$1301,"<="&Assumptions!$C$6),0) -> 0.13087164
B11: Dairy | C11: =SUMIFS(Raw!$E$2:$E$1301,Raw!$D$2:$D$1301,$B11,Raw!$A$2:$A$1301,">"&(Assumptions!$C$6-91),Raw!$A$2:$A$1301,"<="&Assumptions!$C$6) -> 41077.49 | D11: =SUMIFS(Raw!$E$2:$E$1301,Raw!$D$2:$D$1301,$B11,Raw!$A$2:$A$1301,">"&(Assumptions!$C$6-182),Raw!$A$2:$A$1301,"<="&(Assumptions!$C$6-91)) -> 41399.79 | E11: =IFERROR(C11/D11-1,0) -> -0.0077850636 | F11: =SUMIFS(Raw!$G$2:$G$1301,Raw!$D$2:$D$1301,$B11,Raw!$A$2:$A$1301,">"&(Assumptions!$C$6-91),Raw!$A$2:$A$1301,"<="&Assumptions!$C$6) -> 11413.34 | G11: =IFERROR(F11/C11,0) -> 0.27784901 | H11: =IFERROR(C11/SUMIFS(Raw!$E$2:$E$1301,Raw!$A$2:$A$1301,">"&(Assumptions!$C$6-91),Raw!$A$2:$A$1301,"<="&Assumptions!$C$6),0) -> 0.16516415
B12: Food To Go | C12: =SUMIFS(Raw!$E$2:$E$1301,Raw!$D$2:$D$1301,$B12,Raw!$A$2:$A$1301,">"&(Assumptions!$C$6-91),Raw!$A$2:$A$1301,"<="&Assumptions!$C$6) -> 44542.2 | D12: =SUMIFS(Raw!$E$2:$E$1301,Raw!$D$2:$D$1301,$B12,Raw!$A$2:$A$1301,">"&(Assumptions!$C$6-182),Raw!$A$2:$A$1301,"<="&(Assumptions!$C$6-91)) -> 45477.13 | E12: =IFERROR(C12/D12-1,0) -> -0.020558245 | F12: =SUMIFS(Raw!$G$2:$G$1301,Raw!$D$2:$D$1301,$B12,Raw!$A$2:$A$1301,">"&(Assumptions!$C$6-91),Raw!$A$2:$A$1301,"<="&Assumptions!$C$6) -> 21615.4 | G12: =IFERROR(F12/C12,0) -> 0.48527913 | H12: =IFERROR(C12/SUMIFS(Raw!$E$2:$E$1301,Raw!$A$2:$A$1301,">"&(Assumptions!$C$6-91),Raw!$A$2:$A$1301,"<="&Assumptions!$C$6),0) -> 0.17909504
B13: Frozen | C13: =SUMIFS(Raw!$E$2:$E$1301,Raw!$D$2:$D$1301,$B13,Raw!$A$2:$A$1301,">"&(Assumptions!$C$6-91),Raw!$A$2:$A$1301,"<="&Assumptions!$C$6) -> 18150.25 | D13: =SUMIFS(Raw!$E$2:$E$1301,Raw!$D$2:$D$1301,$B13,Raw!$A$2:$A$1301,">"&(Assumptions!$C$6-182),Raw!$A$2:$A$1301,"<="&(Assumptions!$C$6-91)) -> 17097.51 | E13: =IFERROR(C13/D13-1,0) -> 0.061572709 | F13: =SUMIFS(Raw!$G$2:$G$1301,Raw!$D$2:$D$1301,$B13,Raw!$A$2:$A$1301,">"&(Assumptions!$C$6-91),Raw!$A$2:$A$1301,"<="&Assumptions!$C$6) -> 7785.55 | G13: =IFERROR(F13/C13,0) -> 0.42895001 | H13: =IFERROR(C13/SUMIFS(Raw!$E$2:$E$1301,Raw!$A$2:$A$1301,">"&(Assumptions!$C$6-91),Raw!$A$2:$A$1301,"<="&Assumptions!$C$6),0) -> 0.072978427
B14: Grocery | C14: =SUMIFS(Raw!$E$2:$E$1301,Raw!$D$2:$D$1301,$B14,Raw!$A$2:$A$1301,">"&(Assumptions!$C$6-91),Raw!$A$2:$A$1301,"<="&Assumptions!$C$6) -> 27410.41 | D14: =SUMIFS(Raw!$E$2:$E$1301,Raw!$D$2:$D$1301,$B14,Raw!$A$2:$A$1301,">"&(Assumptions!$C$6-182),Raw!$A$2:$A$1301,"<="&(Assumptions!$C$6-91)) -> 25565.51 | E14: =IFERROR(C14/D14-1,0) -> 0.07216363 | F14: =SUMIFS(Raw!$G$2:$G$1301,Raw!$D$2:$D$1301,$B14,Raw!$A$2:$A$1301,">"&(Assumptions!$C$6-91),Raw!$A$2:$A$1301,"<="&Assumptions!$C$6) -> 9595.31 | G14: =IFERROR(F14/C14,0) -> 0.3500608 | H14: =IFERROR(C14/SUMIFS(Raw!$E$2:$E$1301,Raw!$A$2:$A$1301,">"&(Assumptions!$C$6-91),Raw!$A$2:$A$1301,"<="&Assumptions!$C$6),0) -> 0.11021163
B15: Health & Beauty | C15: =SUMIFS(Raw!$E$2:$E$1301,Raw!$D$2:$D$1301,$B15,Raw!$A$2:$A$1301,">"&(Assumptions!$C$6-91),Raw!$A$2:$A$1301,"<="&Assumptions!$C$6) -> 4308.91 | D15: =SUMIFS(Raw!$E$2:$E$1301,Raw!$D$2:$D$1301,$B15,Raw!$A$2:$A$1301,">"&(Assumptions!$C$6-182),Raw!$A$2:$A$1301,"<="&(Assumptions!$C$6-91)) -> 3953.68 | E15: =IFERROR(C15/D15-1,0) -> 0.089847939 | F15: =SUMIFS(Raw!$G$2:$G$1301,Raw!$D$2:$D$1301,$B15,Raw!$A$2:$A$1301,">"&(Assumptions!$C$6-91),Raw!$A$2:$A$1301,"<="&Assumptions!$C$6) -> 2172.91 | G15: =IFERROR(F15/C15,0) -> 0.50428299 | H15: =IFERROR(C15/SUMIFS(Raw!$E$2:$E$1301,Raw!$A$2:$A$1301,">"&(Assumptions!$C$6-91),Raw!$A$2:$A$1301,"<="&Assumptions!$C$6),0) -> 0.017325242
B16: Household | C16: =SUMIFS(Raw!$E$2:$E$1301,Raw!$D$2:$D$1301,$B16,Raw!$A$2:$A$1301,">"&(Assumptions!$C$6-91),Raw!$A$2:$A$1301,"<="&Assumptions!$C$6) -> 6861.82 | D16: =SUMIFS(Raw!$E$2:$E$1301,Raw!$D$2:$D$1301,$B16,Raw!$A$2:$A$1301,">"&(Assumptions!$C$6-182),Raw!$A$2:$A$1301,"<="&(Assumptions!$C$6-91)) -> 6891.88 | E16: =IFERROR(C16/D16-1,0) -> -0.0043616546 | F16: =SUMIFS(Raw!$G$2:$G$1301,Raw!$D$2:$D$1301,$B16,Raw!$A$2:$A$1301,">"&(Assumptions!$C$6-91),Raw!$A$2:$A$1301,"<="&Assumptions!$C$6) -> 2865.22 | G16: =IFERROR(F16/C16,0) -> 0.41755977 | H16: =IFERROR(C16/SUMIFS(Raw!$E$2:$E$1301,Raw!$A$2:$A$1301,">"&(Assumptions!$C$6-91),Raw!$A$2:$A$1301,"<="&Assumptions!$C$6),0) -> 0.027589969
B17: Produce | C17: =SUMIFS(Raw!$E$2:$E$1301,Raw!$D$2:$D$1301,$B17,Raw!$A$2:$A$1301,">"&(Assumptions!$C$6-91),Raw!$A$2:$A$1301,"<="&Assumptions!$C$6) -> 5268.71 | D17: =SUMIFS(Raw!$E$2:$E$1301,Raw!$D$2:$D$1301,$B17,Raw!$A$2:$A$1301,">"&(Assumptions!$C$6-182),Raw!$A$2:$A$1301,"<="&(Assumptions!$C$6-91)) -> 5562.97 | E17: =IFERROR(C17/D17-1,0) -> -0.052896205 | F17: =SUMIFS(Raw!$G$2:$G$1301,Raw!$D$2:$D$1301,$B17,Raw!$A$2:$A$1301,">"&(Assumptions!$C$6-91),Raw!$A$2:$A$1301,"<="&Assumptions!$C$6) -> 2261.73 | G17: =IFERROR(F17/C17,0) -> 0.42927586 | H17: =IFERROR(C17/SUMIFS(Raw!$E$2:$E$1301,Raw!$A$2:$A$1301,">"&(Assumptions!$C$6-91),Raw!$A$2:$A$1301,"<="&Assumptions!$C$6),0) -> 0.021184401
B18: Snacks & Confectionery | C18: =SUMIFS(Raw!$E$2:$E$1301,Raw!$D$2:$D$1301,$B18,Raw!$A$2:$A$1301,">"&(Assumptions!$C$6-91),Raw!$A$2:$A$1301,"<="&Assumptions!$C$6) -> 26511.06 | D18: =SUMIFS(Raw!$E$2:$E$1301,Raw!$D$2:$D$1301,$B18,Raw!$A$2:$A$1301,">"&(Assumptions!$C$6-182),Raw!$A$2:$A$1301,"<="&(Assumptions!$C$6-91)) -> 25928.13 | E18: =IFERROR(C18/D18-1,0) -> 0.022482532 | F18: =SUMIFS(Raw!$G$2:$G$1301,Raw!$D$2:$D$1301,$B18,Raw!$A$2:$A$1301,">"&(Assumptions!$C$6-91),Raw!$A$2:$A$1301,"<="&Assumptions!$C$6) -> 11709.76 | G18: =IFERROR(F18/C18,0) -> 0.44169339 | H18: =IFERROR(C18/SUMIFS(Raw!$E$2:$E$1301,Raw!$A$2:$A$1301,">"&(Assumptions!$C$6-91),Raw!$A$2:$A$1301,"<="&Assumptions!$C$6),0) -> 0.10659553
B19: Total | C19: =SUM(C8:C18) -> 248707.06 | D19: =SUM(D8:D18) -> 245203.22 | E19: =IFERROR(C19/D19-1,0) -> 0.014289535 | F19: =SUM(F8:F18) -> 101049.93 | G19: =IFERROR(F19/C19,0) -> 0.40630101 | H19: =1 -> 1
B22: Products (use the filter buttons; 'In selection' follows the Category cell)
B24: SKU | C24: Product | D24: Category | E24: Sales 13w | F24: Prior 13w | G24: Change | H24: GM % | I24: ABC | J24: Range call | K24: In selection
B25: BAK001 | C25: =INDEX(Lookup!$C$7:$C$56,MATCH($B25,Lookup!$B$7:$B$56,0)) -> Toast Bread White | D25: =INDEX(Lookup!$D$7:$D$56,MATCH($B25,Lookup!$B$7:$B$56,0)) -> Bakery | E25: =SUMIFS(Raw!$E$2:$E$1301,Raw!$B$2:$B$1301,$B25,Raw!$A$2:$A$1301,">"&(Assumptions!$C$6-91),Raw!$A$2:$A$1301,"<="&Assumptions!$C$6) -> 6592.61 | F25: =SUMIFS(Raw!$E$2:$E$1301,Raw!$B$2:$B$1301,$B25,Raw!$A$2:$A$1301,">"&(Assumptions!$C$6-182),Raw!$A$2:$A$1301,"<="&(Assumptions!$C$6-91)) -> 6394.03 | G25: =IFERROR(E25/F25-1,0) -> 0.031057095 | H25: =IFERROR(SUMIFS(Raw!$G$2:$G$1301,Raw!$B$2:$B$1301,$B25,Raw!$A$2:$A$1301,">"&(Assumptions!$C$6-91),Raw!$A$2:$A$1301,"<="&Assumptions!$C$6)/E25,0) -> 0.36962751 | I25: =INDEX(Lookup!$E$7:$E$56,MATCH($B25,Lookup!$B$7:$B$56,0)) -> A | J25: =INDEX(Lookup!$G$7:$G$56,MATCH($B25,Lookup!$B$7:$B$56,0)) -> Protect availability | K25: =IF(OR(SelCat="All",D25=SelCat),1,0) -> 1
B26: BAK002 | C26: =INDEX(Lookup!$C$7:$C$56,MATCH($B26,Lookup!$B$7:$B$56,0)) -> Wholemeal Loaf | D26: =INDEX(Lookup!$D$7:$D$56,MATCH($B26,Lookup!$B$7:$B$56,0)) -> Bakery | E26: =SUMIFS(Raw!$E$2:$E$1301,Raw!$B$2:$B$1301,$B26,Raw!$A$2:$A$1301,">"&(Assumptions!$C$6-91),Raw!$A$2:$A$1301,"<="&Assumptions!$C$6) -> 4483.05 | F26: =SUMIFS(Raw!$E$2:$E$1301,Raw!$B$2:$B$1301,$B26,Raw!$A$2:$A$1301,">"&(Assumptions!$C$6-182),Raw!$A$2:$A$1301,"<="&(Assumptions!$C$6-91)) -> 4632.99 | G26: =IFERROR(E26/F26-1,0) -> -0.032363549 | H26: =IFERROR(SUMIFS(Raw!$G$2:$G$1301,Raw!$B$2:$B$1301,$B26,Raw!$A$2:$A$1301,">"&(Assumptions!$C$6-91),Raw!$A$2:$A$1301,"<="&Assumptions!$C$6)/E26,0) -> 0.37062937 | I26: =INDEX(Lookup!$E$7:$E$56,MATCH($B26,Lookup!$B$7:$B$56,0)) -> A | J26: =INDEX(Lookup!$G$7:$G$56,MATCH($B26,Lookup!$B$7:$B$56,0)) -> Protect availability | K26: =IF(OR(SelCat="All",D26=SelCat),1,0) -> 1
B27: BAK003 | C27: =INDEX(Lookup!$C$7:$C$56,MATCH($B27,Lookup!$B$7:$B$56,0)) -> Croissant 4pk | D27: =INDEX(Lookup!$D$7:$D$56,MATCH($B27,Lookup!$B$7:$B$56,0)) -> Bakery | E27: =SUMIFS(Raw!$E$2:$E$1301,Raw!$B$2:$B$1301,$B27,Raw!$A$2:$A$1301,">"&(Assumptions!$C$6-91),Raw!$A$2:$A$1301,"<="&Assumptions!$C$6) -> 3578.25 | F27: =SUMIFS(Raw!$E$2:$E$1301,Raw!$B$2:$B$1301,$B27,Raw!$A$2:$A$1301,">"&(Assumptions!$C$6-182),Raw!$A$2:$A$1301,"<="&(Assumptions!$C$6-91)) -> 3318.46 | G27: =IFERROR(E27/F27-1,0) -> 0.078286314 | H27: =IFERROR(SUMIFS(Raw!$G$2:$G$1301,Raw!$B$2:$B$1301,$B27,Raw!$A$2:$A$1301,">"&(Assumptions!$C$6-91),Raw!$A$2:$A$1301,"<="&Assumptions!$C$6)/E27,0) -> 0.43282331 | I27: =INDEX(Lookup!$E$7:$E$56,MATCH($B27,Lookup!$B$7:$B$56,0)) -> B | J27: =INDEX(Lookup!$G$7:$G$56,MATCH($B27,Lookup!$B$7:$B$56,0)) -> Maintain | K27: =IF(OR(SelCat="All",D27=SelCat),1,0) -> 1
B28: LIQ001 | C28: =INDEX(Lookup!$C$7:$C$56,MATCH($B28,Lookup!$B$7:$B$56,0)) -> Craft Beer 6pk | D28: =INDEX(Lookup!$D$7:$D$56,MATCH($B28,Lookup!$B$7:$B$56,0)) -> Beer & Wine | E28: =SUMIFS(Raw!$E$2:$E$1301,Raw!$B$2:$B$1301,$B28,Raw!$A$2:$A$1301,">"&(Assumptions!$C$6-91),Raw!$A$2:$A$1301,"<="&Assumptions!$C$6) -> 10901.79 | F28: =SUMIFS(Raw!$E$2:$E$1301,Raw!$B$2:$B$1301,$B28,Raw!$A$2:$A$1301,">"&(Assumptions!$C$6-182),Raw!$A$2:$A$1301,"<="&(Assumptions!$C$6-91)) -> 9393.67 | G28: =IFERROR(E28/F28-1,0) -> 0.16054641 | H28: =IFERROR(SUMIFS(Raw!$G$2:$G$1301,Raw!$B$2:$B$1301,$B28,Raw!$A$2:$A$1301,">"&(Assumptions!$C$6-91),Raw!$A$2:$A$1301,"<="&Assumptions!$C$6)/E28,0) -> 0.32494572 | I28: =INDEX(Lookup!$E$7:$E$56,MATCH($B28,Lookup!$B$7:$B$56,0)) -> A | J28: =INDEX(Lookup!$G$7:$G$56,MATCH($B28,Lookup!$B$7:$B$56,0)) -> Protect availability | K28: =IF(OR(SelCat="All",D28=SelCat),1,0) -> 1
B29: LIQ003 | C29: =INDEX(Lookup!$C$7:$C$56,MATCH($B29,Lookup!$B$7:$B$56,0)) -> RTD 4pk | D29: =INDEX(Lookup!$D$7:$D$56,MATCH($B29,Lookup!$B$7:$B$56,0)) -> Beer & Wine | E29: =SUMIFS(Raw!$E$2:$E$1301,Raw!$B$2:$B$1301,$B29,Raw!$A$2:$A$1301,">"&(Assumptions!$C$6-91),Raw!$A$2:$A$1301,"<="&Assumptions!$C$6) -> 6422.43 | F29: =SUMIFS(Raw!$E$2:$E$1301,Raw!$B$2:$B$1301,$B29,Raw!$A$2:$A$1301,">"&(Assumptions!$C$6-182),Raw!$A$2:$A$1301,"<="&(Assumptions!$C$6-91)) -> 6343.23 | G29: =IFERROR(E29/F29-1,0) -> 0.012485753 | H29: =IFERROR(SUMIFS(Raw!$G$2:$G$1301,Raw!$B$2:$B$1301,$B29,Raw!$A$2:$A$1301,">"&(Assumptions!$C$6-91),Raw!$A$2:$A$1301,"<="&Assumptions!$C$6)/E29,0) -> 0.3385214 | I29: =INDEX(Lookup!$E$7:$E$56,MATCH($B29,Lookup!$B$7:$B$56,0)) -> A | J29: =INDEX(Lookup!$G$7:$G$56,MATCH($B29,Lookup!$B$7:$B$56,0)) -> Protect availability | K29: =IF(OR(SelCat="All",D29=SelCat),1,0) -> 1
B30: LIQ002 | C30: =INDEX(Lookup!$C$7:$C$56,MATCH($B30,Lookup!$B$7:$B$56,0)) -> Sauvignon Blanc 750ml | D30: =INDEX(Lookup!$D$7:$D$56,MATCH($B30,Lookup!$B$7:$B$56,0)) -> Beer & Wine | E30: =SUMIFS(Raw!$E$2:$E$1301,Raw!$B$2:$B$1301,$B30,Raw!$A$2:$A$1301,">"&(Assumptions!$C$6-91),Raw!$A$2:$A$1301,"<="&Assumptions!$C$6) -> 6063.39 | F30: =SUMIFS(Raw!$E$2:$E$1301,Raw!$B$2:$B$1301,$B30,Raw!$A$2:$A$1301,">"&(Assumptions!$C$6-182),Raw!$A$2:$A$1301,"<="&(Assumptions!$C$6-91)) -> 6332.04 | G30: =IFERROR(E30/F30-1,0) -> -0.042427085 | H30: =IFERROR(SUMIFS(Raw!$G$2:$G$1301,Raw!$B$2:$B$1301,$B30,Raw!$A$2:$A$1301,">"&(Assumptions!$C$6-91),Raw!$A$2:$A$1301,"<="&Assumptions!$C$6)/E30,0) -> 0.35907141 | I30: =INDEX(Lookup!$E$7:$E$56,MATCH($B30,Lookup!$B$7:$B$56,0)) -> A | J30: =INDEX(Lookup!$G$7:$G$56,MATCH($B30,Lookup!$B$7:$B$56,0)) -> Protect availability | K30: =IF(OR(SelCat="All",D30=SelCat),1,0) -> 1
B31: LIQ004 | C31: =INDEX(Lookup!$C$7:$C$56,MATCH($B31,Lookup!$B$7:$B$56,0)) -> Pinot Noir 750ml | D31: =INDEX(Lookup!$D$7:$D$56,MATCH($B31,Lookup!$B$7:$B$56,0)) -> Beer & Wine | E31: =SUMIFS(Raw!$E$2:$E$1301,Raw!$B$2:$B$1301,$B31,Raw!$A$2:$A$1301,">"&(Assumptions!$C$6-91),Raw!$A$2:$A$1301,"<="&Assumptions!$C$6) -> 3985.99 | F31: =SUMIFS(Raw!$E$2:$E$1301,Raw!$B$2:$B$1301,$B31,Raw!$A$2:$A$1301,">"&(Assumptions!$C$6-182),Raw!$A$2:$A$1301,"<="&(Assumptions!$C$6-91)) -> 4137.9 | G31: =IFERROR(E31/F31-1,0) -> -0.036711859 | H31: =IFERROR(SUMIFS(Raw!$G$2:$G$1301,Raw!$B$2:$B$1301,$B31,Raw!$A$2:$A$1301,">"&(Assumptions!$C$6-91),Raw!$A$2:$A$1301,"<="&Assumptions!$C$6)/E31,0) -> 0.35453927 | I31: =INDEX(Lookup!$E$7:$E$56,MATCH($B31,Lookup!$B$7:$B$56,0)) -> A | J31: =INDEX(Lookup!$G$7:$G$56,MATCH($B31,Lookup!$B$7:$B$56,0)) -> Protect availability | K31: =IF(OR(SelCat="All",D31=SelCat),1,0) -> 1
B32: BEV001 | C32: =INDEX(Lookup!$C$7:$C$56,MATCH($B32,Lookup!$B$7:$B$56,0)) -> Energy Drink 500ml | D32: =INDEX(Lookup!$D$7:$D$56,MATCH($B32,Lookup!$B$7:$B$56,0)) -> Beverages | E32: =SUMIFS(Raw!$E$2:$E$1301,Raw!$B$2:$B$1301,$B32,Raw!$A$2:$A$1301,">"&(Assumptions!$C$6-91),Raw!$A$2:$A$1301,"<="&Assumptions!$C$6) -> 10050.38 | F32: =SUMIFS(Raw!$E$2:$E$1301,Raw!$B$2:$B$1301,$B32,Raw!$A$2:$A$1301,">"&(Assumptions!$C$6-182),Raw!$A$2:$A$1301,"<="&(Assumptions!$C$6-91)) -> 9331.35 | G32: =IFERROR(E32/F32-1,0) -> 0.077055303 | H32: =IFERROR(SUMIFS(Raw!$G$2:$G$1301,Raw!$B$2:$B$1301,$B32,Raw!$A$2:$A$1301,">"&(Assumptions!$C$6-91),Raw!$A$2:$A$1301,"<="&Assumptions!$C$6)/E32,0) -> 0.49385993 | I32: =INDEX(Lookup!$E$7:$E$56,MATCH($B32,Lookup!$B$7:$B$56,0)) -> A | J32: =INDEX(Lookup!$G$7:$G$56,MATCH($B32,Lookup!$B$7:$B$56,0)) -> Protect availability | K32: =IF(OR(SelCat="All",D32=SelCat),1,0) -> 1
B33: BEV002 | C33: =INDEX(Lookup!$C$7:$C$56,MATCH($B33,Lookup!$B$7:$B$56,0)) -> Cola 1.5L | D33: =INDEX(Lookup!$D$7:$D$56,MATCH($B33,Lookup!$B$7:$B$56,0)) -> Beverages | E33: =SUMIFS(Raw!$E$2:$E$1301,Raw!$B$2:$B$1301,$B33,Raw!$A$2:$A$1301,">"&(Assumptions!$C$6-91),Raw!$A$2:$A$1301,"<="&Assumptions!$C$6) -> 5194.93 | F33: =SUMIFS(Raw!$E$2:$E$1301,Raw!$B$2:$B$1301,$B33,Raw!$A$2:$A$1301,">"&(Assumptions!$C$6-182),Raw!$A$2:$A$1301,"<="&(Assumptions!$C$6-91)) -> 5159.01 | G33: =IFERROR(E33/F33-1,0) -> 0.0069625762 | H33: =IFERROR(SUMIFS(Raw!$G$2:$G$1301,Raw!$B$2:$B$1301,$B33,Raw!$A$2:$A$1301,">"&(Assumptions!$C$6-91),Raw!$A$2:$A$1301,"<="&Assumptions!$C$6)/E33,0) -> 0.48775056 | I33: =INDEX(Lookup!$E$7:$E$56,MATCH($B33,Lookup!$B$7:$B$56,0)) -> A | J33: =INDEX(Lookup!$G$7:$G$56,MATCH($B33,Lookup!$B$7:$B$56,0)) -> Protect availability | K33: =IF(OR(SelCat="All",D33=SelCat),1,0) -> 1
B34: BEV004 | C34: =INDEX(Lookup!$C$7:$C$56,MATCH($B34,Lookup!$B$7:$B$56,0)) -> Iced Coffee 500ml | D34: =INDEX(Lookup!$D$7:$D$56,MATCH($B34,Lookup!$B$7:$B$56,0)) -> Beverages | E34: =SUMIFS(Raw!$E$2:$E$1301,Raw!$B$2:$B$1301,$B34,Raw!$A$2:$A$1301,">"&(Assumptions!$C$6-91),Raw!$A$2:$A$1301,"<="&Assumptions!$C$6) -> 5064.85 | F34: =SUMIFS(Raw!$E$2:$E$1301,Raw!$B$2:$B$1301,$B34,Raw!$A$2:$A$1301,">"&(Assumptions!$C$6-182),Raw!$A$2:$A$1301,"<="&(Assumptions!$C$6-91)) -> 5464.05 | G34: =IFERROR(E34/F34-1,0) -> -0.073059361 | H34: =IFERROR(SUMIFS(Raw!$G$2:$G$1301,Raw!$B$2:$B$1301,$B34,Raw!$A$2:$A$1301,">"&(Assumptions!$C$6-91),Raw!$A$2:$A$1301,"<="&Assumptions!$C$6)/E34,0) -> 0.45891784 | I34: =INDEX(Lookup!$E$7:$E$56,MATCH($B34,Lookup!$B$7:$B$56,0)) -> A | J34: =INDEX(Lookup!$G$7:$G$56,MATCH($B34,Lookup!$B$7:$B$56,0)) -> Protect availability | K34: =IF(OR(SelCat="All",D34=SelCat),1,0) -> 1
B35: BEV006 | C35: =INDEX(Lookup!$C$7:$C$56,MATCH($B35,Lookup!$B$7:$B$56,0)) -> Bottled Water 750ml | D35: =INDEX(Lookup!$D$7:$D$56,MATCH($B35,Lookup!$B$7:$B$56,0)) -> Beverages | E35: =SUMIFS(Raw!$E$2:$E$1301,Raw!$B$2:$B$1301,$B35,Raw!$A$2:$A$1301,">"&(Assumptions!$C$6-91),Raw!$A$2:$A$1301,"<="&Assumptions!$C$6) -> 4807.92 | F35: =SUMIFS(Raw!$E$2:$E$1301,Raw!$B$2:$B$1301,$B35,Raw!$A$2:$A$1301,">"&(Assumptions!$C$6-182),Raw!$A$2:$A$1301,"<="&(Assumptions!$C$6-91)) -> 4876.69 | G35: =IFERROR(E35/F35-1,0) -> -0.014101778 | H35: =IFERROR(SUMIFS(Raw!$G$2:$G$1301,Raw!$B$2:$B$1301,$B35,Raw!$A$2:$A$1301,">"&(Assumptions!$C$6-91),Raw!$A$2:$A$1301,"<="&Assumptions!$C$6)/E35,0) -> 0.68227425 | I35: =INDEX(Lookup!$E$7:$E$56,MATCH($B35,Lookup!$B$7:$B$56,0)) -> A | J35: =INDEX(Lookup!$G$7:$G$56,MATCH($B35,Lookup!$B$7:$B$56,0)) -> Protect availability | K35: =IF(OR(SelCat="All",D35=SelCat),1,0) -> 1
B36: BBT001 | C36: =INDEX(Lookup!$C$7:$C$56,MATCH($B36,Lookup!$B$7:$B$56,0)) -> Bubble Tea Kit | D36: =INDEX(Lookup!$D$7:$D$56,MATCH($B36,Lookup!$B$7:$B$56,0)) -> Beverages | E36: =SUMIFS(Raw!$E$2:$E$1301,Raw!$B$2:$B$1301,$B36,Raw!$A$2:$A$1301,">"&(Assumptions!$C$6-91),Raw!$A$2:$A$1301,"<="&Assumptions!$C$6) -> 2823.96 | F36: =SUMIFS(Raw!$E$2:$E$1301,Raw!$B$2:$B$1301,$B36,Raw!$A$2:$A$1301,">"&(Assumptions!$C$6-182),Raw!$A$2:$A$1301,"<="&(Assumptions!$C$6-91)) -> 3092.25 | G36: =IFERROR(E36/F36-1,0) -> -0.086762066 | H36: =IFERROR(SUMIFS(Raw!$G$2:$G$1301,Raw!$B$2:$B$1301,$B36,Raw!$A$2:$A$1301,">"&(Assumptions!$C$6-91),Raw!$A$2:$A$1301,"<="&Assumptions!$C$6)/E36,0) -> 0.44206009 | I36: =INDEX(Lookup!$E$7:$E$56,MATCH($B36,Lookup!$B$7:$B$56,0)) -> B | J36: =INDEX(Lookup!$G$7:$G$56,MATCH($B36,Lookup!$B$7:$B$56,0)) -> Maintain | K36: =IF(OR(SelCat="All",D36=SelCat),1,0) -> 1
... B74: SNK005 | C74: =INDEX(Lookup!$C$7:$C$56,MATCH($B74,Lookup!$B$7:$B$56,0)) -> Lollies Bag 200g | D74: =INDEX(Lookup!$D$7:$D$56,MATCH($B74,Lookup!$B$7:$B$56,0)) -> Snacks & Confectionery | E74: =SUMIFS(Raw!$E$2:$E$1301,Raw!$B$2:$B$1301,$B74,Raw!$A$2:$A$1301,">"&(Assumptions!$C$6-91),Raw!$A$2:$A$1301,"<="&Assumptions!$C$6) -> 3074.69 | F74: =SUMIFS(Raw!$E$2:$E$1301,Raw!$B$2:$B$1301,$B74,Raw!$A$2:$A$1301,">"&(Assumptions!$C$6-182),Raw!$A$2:$A$1301,"<="&(Assumptions!$C$6-91)) -> 3033.34 | G74: =IFERROR(E74/F74-1,0) -> 0.013631838 | H74: =IFERROR(SUMIFS(Raw!$G$2:$G$1301,Raw!$B$2:$B$1301,$B74,Raw!$A$2:$A$1301,">"&(Assumptions!$C$6-91),Raw!$A$2:$A$1301,"<="&Assumptions!$C$6)/E74,0) -> 0.51289398 | I74: =INDEX(Lookup!$E$7:$E$56,MATCH($B74,Lookup!$B$7:$B$56,0)) -> B | J74: =INDEX(Lookup!$G$7:$G$56,MATCH($B74,Lookup!$B$7:$B$56,0)) -> Maintain | K74: =IF(OR(SelCat="All",D74=SelCat),1,0) -> 1

Sheet Pivot
B1: SHELLY
B2: Pivot tables
B3: Real Excel PivotTables over the Raw sheet: drag fields in the PivotTable pane to explore. They refresh when the file opens.
A5: Sales by product (filter Category)
A6: Category | B6: (All)
A8: Row Labels | B8: Sales
A9: Avocado | B9: 3299.05
A10: Bananas (each) | B10: 3949.64
A11: Bottled Water 750ml | B11: 9684.61
A12: Bubble Tea Kit | B12: 5916.21
A13: Butter 500g | B13: 8306.26
A14: Canned Soup 500g | B14: 3806.47
A15: Cheese Block 1kg | B15: 12876.36
A16: Chicken Sandwich | B16: 25983.94
A17: Chocolate Block 200g | B17: 16851.76
A18: Coffee Beans 200g | B18: 7004.53
A19: Cola 1.5L | B19: 10353.94
A20: Corn Chips 230g | B20: 7246.86
... A59: Grand Total | B59: 493910.28
A63: Weekly sales by category
A64: Sales | B64: Column Labels
A65: Row Labels | B65: Bakery | C65: Beer & Wine | D65: Beverages | E65: Dairy | F65: Food To Go | G65: Frozen | H65: Grocery | I65: Health & Beauty | J65: Household | K65: Produce | L65: Snacks & Confectionery | M65: Grand Total
A66: 2026-04-19 | B66: 1156.08 | C66: 2152.62 | D66: 3134.45 | E66: 3229.94 | F66: 3499.45 | G66: 1341.96 | H66: 1893.15 | I66: 282.65 | J66: 357.58 | K66: 517.52 | L66: 1962.73 | M66: 19528.13
A67: 2026-04-26 | B67: 1096.28 | C67: 2393.78 | D67: 2837.06 | E67: 3440.42 | F67: 3400.87 | G67: 1303.1 | H67: 1902.67 | I67: 305.62 | J67: 619.3 | K67: 420.08 | L67: 2171.6 | M67: 19890.78
A68: 2026-05-03 | B68: 982.92 | C68: 1961.73 | D68: 2428.51 | E68: 3085.83 | F68: 3321.61 | G68: 1435.98 | H68: 1740.92 | I68: 317.59 | J68: 622.27 | K68: 445.5 | L68: 1835.1 | M68: 18177.96
A69: 2026-05-10 | B69: 1167.53 | C69: 2399.74 | D69: 2772.37 | E69: 3016.88 | F69: 3518.87 | G69: 1195.81 | H69: 1835.21 | I69: 281.57 | J69: 489.36 | K69: 435.37 | L69: 2179.88 | M69: 19292.59
A70: 2026-05-17 | B70: 1150.06 | C70: 2034.92 | D70: 2682.9 | E70: 3393.28 | F70: 3595.87 | G70: 1271.21 | H70: 2164.28 | I70: 286.53 | J70: 602.33 | K70: 430.82 | L70: 2050.49 | M70: 19662.69
A71: 2026-05-24 | B71: 1057.98 | C71: 2292.8 | D71: 2509.17 | E71: 3178.04 | F71: 3655.07 | G71: 1389.11 | H71: 2170.76 | I71: 391.08 | J71: 498.37 | K71: 466.38 | L71: 1873.6 | M71: 19482.36
A72: 2026-05-31 | B72: 948.81 | C72: 2179.9 | D72: 2380.65 | E72: 3284.02 | F72: 4024.65 | G72: 1593.93 | H72: 1617.5 | I72: 371.4 | J72: 477.44 | K72: 512.88 | L72: 1858.35 | M72: 19249.53
A73: 2026-06-07 | B73: 1091.19 | C73: 1812.05 | D73: 2485.72 | E73: 3114.96 | F73: 3202.24 | G73: 1226.2 | H73: 2108.06 | I73: 260.54 | J73: 564.35 | K73: 397.17 | L73: 1989.75 | M73: 18252.23
A74: 2026-06-14 | B74: 1085.78 | C74: 1738.09 | D74: 2371.5 | E74: 3312.22 | F74: 3772.1 | G74: 1358.27 | H74: 2169.26 | I74: 325.57 | J74: 589.3 | K74: 396.81 | L74: 2043.79 | M74: 19162.69
A75: 2026-06-21 | B75: 1169.03 | C75: 2065.88 | D75: 2299.65 | E75: 3149.66 | F75: 3232.96 | G75: 1287.13 | H75: 1901.57 | I75: 340.45 | J75: 380.53 | K75: 367.55 | L75: 2038.36 | M75: 18232.77
A76: 2026-06-28 | B76: 1102.44 | C76: 1709.11 | D76: 2316.25 | E76: 2920.04 | F76: 3721.16 | G76: 1272.24 | H76: 1901.56 | I76: 260.54 | J76: 628.27 | K76: 347.7 | L76: 2147.62 | M76: 18326.93
A77: 2026-07-05 | B77: 1127.27 | C77: 1529.21 | D77: 2353.76 | E77: 3270.95 | F77: 3339.67 | G77: 1202.28 | H77: 2101.54 | I77: 321.47 | J77: 530.39 | K77: 384.14 | L77: 2008.34 | M77: 18169.02
... A92: Grand Total | B92: 28999.39 | C92: 53580.44 | D92: 65323 | E92: 82477.28 | F92: 90019.33 | G92: 35247.76 | H92: 52975.92 | I92: 8262.59 | J92: 13753.7 | K92: 10831.68 | L92: 52439.19 | M92: 493910.28

Sheet Raw
A1: Week ending | B1: SKU | C1: Product | D1: Category | E1: Sales | F1: Units | G1: Gross margin
A2: 46131 | B2: BAK001 | C2: Toast Bread White | D2: Bakery | E2: 582.83 | F2: 167 | G2: 215.43
A3: 46131 | B3: BAK002 | C3: Wholemeal Loaf | D3: Bakery | E3: 291.72 | F3: 68 | G3: 108.12
A4: 46131 | B4: BAK003 | C4: Croissant 4pk | D4: Bakery | E4: 281.53 | F4: 47 | G4: 126.43
A5: 46131 | B5: BBT001 | C5: Bubble Tea Kit | D5: Beverages | E5: 265.62 | F5: 38 | G5: 117.42
A6: 46131 | B6: BEV001 | C6: Energy Drink 500ml | D6: Beverages | E6: 926.64 | F6: 216 | G6: 462.24
A7: 46131 | B7: BEV002 | C7: Cola 1.5L | D7: Beverages | E7: 556.76 | F7: 124 | G7: 271.56
A8: 46131 | B8: BEV003 | C8: Sparkling Water 1L | D8: Beverages | E8: 241.53 | F8: 97 | G8: 134.83
A9: 46131 | B9: BEV004 | C9: Iced Coffee 500ml | D9: Beverages | E9: 484.03 | F9: 97 | G9: 222.13
A10: 46131 | B10: BEV005 | C10: Kombucha 330ml | D10: Beverages | E10: 220.34 | F10: 46 | G10: 100.74
A11: 46131 | B11: BEV006 | C11: Bottled Water 750ml | D11: Beverages | E11: 439.53 | F11: 147 | G11: 299.88
A12: 46131 | B12: DRY010 | C12: Butter 500g | D12: Dairy | E12: 277.13 | F12: 37 | G12: 69.93
A13: 46131 | B13: DRY011 | C13: Greek Yoghurt 1kg | D13: Dairy | E13: 258.83 | F13: 37 | G13: 70.13
... A1301: 46306 | B1301: SNK005 | C1301: Lollies Bag 200g | D1301: Snacks & Confectionery | E1301: 191.95 | F1301: 55 | G1301: 98.45

Sheet Lookup
B1: SHELLY
B2: Lookup tables
B3: Reference data used by INDEX-MATCH formulas in the Model sheet.
B5: products | M5: Category list
B6: SKU | C6: product | D6: category | E6: abc | F6: segment | G6: range_call | H6: reorder | M6: All
B7: BAK001 | C7: Toast Bread White | D7: Bakery | E7: A | F7: Traffic drivers (high velocity) | G7: Protect availability | H7: OK | M7: Bakery
B8: BAK002 | C8: Wholemeal Loaf | D8: Bakery | E8: A | F8: Traffic drivers (high velocity) | G8: Protect availability | H8: OK | M8: Beer & Wine
B9: BAK003 | C9: Croissant 4pk | D9: Bakery | E9: B | F9: Waste-exposed perishables | G9: Maintain | H9: OK | M9: Beverages
B10: BBT001 | C10: Bubble Tea Kit | D10: Beverages | E10: B | F10: Volatile / irregular demand | G10: Maintain | H10: OK | M10: Dairy
B11: BEV001 | C11: Energy Drink 500ml | D11: Beverages | E11: A | F11: Delivery favourites | G11: Protect availability | H11: OK | M11: Food To Go
B12: BEV002 | C12: Cola 1.5L | D12: Beverages | E12: A | F12: Delivery favourites | G12: Protect availability | H12: OK | M12: Frozen
B13: BEV003 | C13: Sparkling Water 1L | D13: Beverages | E13: B | F13: Promo-responsive | G13: Maintain | H13: OK | M13: Grocery
B14: BEV004 | C14: Iced Coffee 500ml | D14: Beverages | E14: A | F14: Delivery favourites | G14: Protect availability | H14: OK | M14: Health & Beauty
B15: BEV005 | C15: Kombucha 330ml | D15: Beverages | E15: B | F15: Promo-responsive | G15: Maintain | H15: OK | M15: Household
B16: BEV006 | C16: Bottled Water 750ml | D16: Beverages | E16: A | F16: Delivery favourites | G16: Protect availability | H16: OK | M16: Produce
B17: DRY010 | C17: Butter 500g | D17: Dairy | E17: A | F17: Promo-responsive | G17: Protect availability | H17: OK | M17: Snacks & Confectionery
B18: DRY011 | C18: Greek Yoghurt 1kg | D18: Dairy | E18: B | F18: Volatile / irregular demand | G18: Maintain | H18: OK
B19: DRY012 | C19: Cheese Block 1kg | D19: Dairy | E19: A | F19: Volatile / irregular demand | G19: Protect availability | H19: OK
B20: FRZ001 | C20: Ice Cream Tub 2L | D20: Frozen | E20: A | F20: Volatile / irregular demand | G20: Protect availability | H20: OK
B21: FRZ002 | C21: Ice Block Single | D21: Frozen | E21: B | F21: Delivery favourites | G21: Maintain | H21: OK
B22: FRZ003 | C22: Frozen Pizza | D22: Frozen | E22: A | F22: Promo-responsive | G22: Protect availability | H22: OK
B23: FRZ004 | C23: Frozen Dumplings 1kg | D23: Frozen | E23: A | F23: Promo-responsive | G23: Protect availability | H23: OK
B24: FTG001 | C24: Chicken Sandwich | D24: Food To Go | E24: A | F24: Waste-exposed perishables | G24: Protect availability | H24: OK
B25: FTG002 | C25: Sushi Pack 8pc | D25: Food To Go | E25: A | F25: Waste-exposed perishables | G25: Protect availability | H25: OK
B26: FTG003 | C26: Hot Pie Mince & Cheese | D26: Food To Go | E26: A | F26: Waste-exposed perishables | G26: Protect availability | H26: OK
B27: FTG004 | C27: Salad Bowl | D27: Food To Go | E27: A | F27: Waste-exposed perishables | G27: Protect availability | H27: OK
B28: FTG005 | C28: Filled Roll | D28: Food To Go | E28: A | F28: Waste-exposed perishables | G28: Protect availability | H28: OK
B29: GRO001 | C29: Instant Noodles 5pk | D29: Grocery | E29: A | F29: Delivery favourites | G29: Protect availability | H29: OK
... B56: SNK005 | C56: Lollies Bag 200g | D56: Snacks & Confectionery | E56: B | F56: Delivery favourites | G56: Maintain | H56: OK
B59: targets
B60: category | C60: gm_target_pct | D60: owner | E60: short_life
B61: Bakery | C61: 0.382 | D61: Store Manager | E61: Yes
B62: Beer & Wine | C62: 0.338 | D62: Licence Manager | E62: No
B63: Beverages | C63: 0.51 | D63: Duty Manager | E63: No
B64: Dairy | C64: 0.278 | D64: Duty Manager | E64: Yes
B65: Food To Go | C65: 0.478 | D65: Store Manager | E65: Yes
B66: Frozen | C66: 0.436 | D66: Duty Manager | E66: No
B67: Grocery | C67: 0.348 | D67: Duty Manager | E67: No
B68: Health & Beauty | C68: 0.501 | D68: Store Manager | E68: No
B69: Household | C69: 0.412 | D69: Duty Manager | E69: No
...

Sheet Assumptions
B1: SHELLY
B2: Assumptions
B3: Blue cells are inputs: change them and every sheet recalculates.
B5: Input | C5: Value | D5: Why / source
B6: Period ends (week ending) | C6: 46306 | D6: 13-week window ends here

Sheet Notes
B1: SHELLY
B2: Notes, method and sign-off
B3: How the numbers were made, what each column means, and who approved it.
B5: About this workbook
C6: Store: Demo Neighbourhood Store (Eden Terrace format). Data to 11 Oct 2026. Shelly v1.19.0.
C7: Synthetic demo data.
C8: Change the blue Category cell on the Dashboard, or any blue input on Assumptions: every formula follows.
B10: Method
C11: 13 weeks = the 91 days ending on the Period ends input; prior = the 91 days before that.
C12: ABC: products ranked by sales; A = top 80% of category sales, B = next 15%, C = last 5%.
C13: Segment and range call come from the K-means segmentation and assortment rules.
B15: Data dictionary (Raw sheet)
B16: Week ending | C16: Last day of the week
B17: SKU | C17: Product code
B18: Sales | C18: Net sales ($)
B19: Units | C19: Units sold
B20: Gross margin | C20: Sales − cost ($)
B22: Sign-off
B23: Range calls agreed | C23: Name: ____________ Date: ________ ☐ Approved ☐ Changes needed
B24: Category owner briefed | C24: Name: ____________ Date: ________ ☐ Approved ☐ Changes needed
B26: Generated by Shelly on 11 Oct 2026 21:21
